Workbook

Sheet DC
A1: Jersey # | B1: Full Name | C1: Goals | D1: Assists | E1: Blocks | F1: Turnovers | G1: Points played | H1: Goals-Semis | I1: Assists-Semis | J1: Blocks-Semis | K1: Turnovers-Semis | L1: Points played-Semis | M1: Goals-Total | N1: Assists-Total | O1: Blocks-Total | P1: Turnovers-Total | Q1: Points played-Total | R1: GABT
A2: 3 | B2: Sami Smalling | C2: 0 | D2: 3 | E2: 1 | F2: 3 | G2: 22 | H2: 3 | I2: 5 | J2: 1 | K2: 1 | L2: 12 | M2: =C2+H2 -> 3 | N2: =D2+I2 -> 8 | O2: =E2+J2 -> 2 | P2: =F2+K2 -> 4 | Q2: =G2+L2 -> 34 | R2: =M2+N2+2*O2-P2*0.5 -> 13
A3: 20 | B3: Kira Flores | C3: 1 | D3: 3 | E3: 0 | F3: 0 | G3: 24 | H3: 3 | I3: 2 | J3: 0 | K3: 4 | L3: 13 | M3: =C3+H3 -> 4 | N3: =D3+I3 -> 5 | O3: =E3+J3 -> 0 | P3: =F3+K3 -> 4 | Q3: =G3+L3 -> 37 | R3: =M3+N3+2*O3-P3*0.5 -> 7
A4: 77 | B4: Marika Korpinen | C4: 1 | D4: 0 | E4: 2 | F4: 0 | G4: 7 | H4: 2 | I4: 0 | J4: 0 | K4: 0 | L4: 10 | M4: =C4+H4 -> 3 | N4: =D4+I4 -> 0 | O4: =E4+J4 -> 2 | P4: =F4+K4 -> 0 | Q4: =G4+L4 -> 17 | R4: =M4+N4+2*O4-P4*0.5 -> 7
A5: 13 | B5: Tyler Smith | C5: 2 | D5: 3 | E5: 0 | F5: 3 | G5: 19 | H5: 1 | I5: 2 | J5: 0 | K5: 0 | L5: 14 | M5: =C5+H5 -> 3 | N5: =D5+I5 -> 5 | O5: =E5+J5 -> 0 | P5: =F5+K5 -> 3 | Q5: =G5+L5 -> 33 | R5: =M5+N5+2*O5-P5*0.5 -> 6.5
A6: 19 | B6: Allie Wallace | C6: 4 | D6: 0 | E6: 0 | F6: 1 | G6: 22 | H6: 2 | I6: 1 | J6: 0 | K6: 0 | L6: 14 | M6: =C6+H6 -> 6 | N6: =D6+I6 -> 1 | O6: =E6+J6 -> 0 | P6: =F6+K6 -> 1 | Q6: =G6+L6 -> 36 | R6: =M6+N6+2*O6-P6*0.5 -> 6.5
A7: 42 | B7: Lisi Lohre | C7: 1 | D7: 0 | E7: 1 | F7: 0 | G7: 11 | H7: 3 | I7: 0 | J7: 0 | K7: 0 | L7: 12 | M7: =C7+H7 -> 4 | N7: =D7+I7 -> 0 | O7: =E7+J7 -> 1 | P7: =F7+K7 -> 0 | Q7: =G7+L7 -> 23 | R7: =M7+N7+2*O7-P7*0.5 -> 6
A8: 12 | B8: Clare Frantz | C8: 3 | D8: 1 | E8: 0 | F8: 1 | G8: 14 | H8: 1 | I8: 1 | J8: 0 | K8: 0 | L8: 12 | M8: =C8+H8 -> 4 | N8: =D8+I8 -> 2 | O8: =E8+J8 -> 0 | P8: =F8+K8 -> 1 | Q8: =G8+L8 -> 26 | R8: =M8+N8+2*O8-P8*0.5 -> 5.5
A9: 4 | B9: Ellen Mueller | C9: 0 | D9: 0 | E9: 0 | F9: 0 | G9: 14 | H9: 1 | I9: 0 | J9: 2 | K9: 0 | L9: 10 | M9: =C9+H9 -> 1 | N9: =D9+I9 -> 0 | O9: =E9+J9 -> 2 | P9: =F9+K9 -> 0 | Q9: =G9+L9 -> 24 | R9: =M9+N9+2*O9-P9*0.5 -> 5
A10: 16 | B10: Marge Walker | C10: 0 | D10: 2 | E10: 0 | F10: 0 | G10: 17 | H10: 1 | I10: 0 | J10: 1 | K10: 1 | L10: 13 | M10: =C10+H10 -> 1 | N10: =D10+I10 -> 2 | O10: =E10+J10 -> 1 | P10: =F10+K10 -> 1 | Q10: =G10+L10 -> 30 | R10: =M10+N10+2*O10-P10*0.5 -> 4.5
A11: 35 | B11: Jordan Sorensen | C11: 2 | D11: 0 | E11: 0 | F11: 0 | G11: 9 | H11: 1 | I11: 0 | J11: 1 | K11: 1 | L11: 12 | M11: =C11+H11 -> 3 | N11: =D11+I11 -> 0 | O11: =E11+J11 -> 1 | P11: =F11+K11 -> 1 | Q11: =G11+L11 -> 21 | R11: =M11+N11+2*O11-P11*0.5 -> 4.5
A12: 11 | B12: Tayara Romero Peña | C12: 0 | D12: 0 | E12: 0 | F12: 0 | G12: 6 | H12: 0 | I12: 0 | J12: 2 | K12: 0 | L12: 10 | M12: =C12+H12 -> 0 | N12: =D12+I12 -> 0 | O12: =E12+J12 -> 2 | P12: =F12+K12 -> 0 | Q12: =G12+L12 -> 16 | R12: =M12+N12+2*O12-P12*0.5 -> 4
A13: 15 | B13: Julia Harris | C13: 1 | D13: 1 | E13: 0 | F13: 0 | G13: 15 | H13: 1 | I13: 1 | J13: 0 | K13: 0 | L13: 10 | M13: =C13+H13 -> 2 | N13: =D13+I13 -> 2 | O13: =E13+J13 -> 0 | P13: =F13+K13 -> 0 | Q13: =G13+L13 -> 25 | R13: =M13+N13+2*O13-P13*0.5 -> 4
... A15: 27 | B15: Jess Sourbeer | C15: 0 | D15: 0 | E15: 1 | F15: 2 | G15: 10 | H15: 1 | I15: 1 | J15: 0 | K15: 0 | L15: 10 | M15: =C15+H15 -> 1 | N15: =D15+I15 -> 1 | O15: =E15+J15 -> 1 | P15: =F15+K15 -> 2 | Q15: =G15+L15 -> 20 | R15: =M15+N15+2*O15-P15*0.5 -> 3
A16: 1 | B16: Ashleigh Jentilet | C16: 0 | D16: 1 | E16: 0 | F16: 1 | G16: 14 | H16: 0 | I16: 0 | J16: 1 | K16: 0 | L16: 4 | M16: =C16+H16 -> 0 | N16: =D16+I16 -> 1 | O16: =E16+J16 -> 1 | P16: =F16+K16 -> 1 | Q16: =G16+L16 -> 18 | R16: =M16+N16+2*O16-P16*0.5 -> 2.5
A17: 8 | B17: Kat Ritzmann | C17: 1 | D17: 2 | E17: 0 | F17: 2 | G17: 17 | H17: 1 | I17: 0 | J17: 0 | K17: 1 | L17: 11 | M17: =C17+H17 -> 2 | N17: =D17+I17 -> 2 | O17: =E17+J17 -> 0 | P17: =F17+K17 -> 3 | Q17: =G17+L17 -> 28 | R17: =M17+N17+2*O17-P17*0.5 -> 2.5
A18: 9 | B18: Annelise Peters | C18: 0 | D18: 0 | E18: 1 | F18: 1 | G18: 6 | H18: 0 | I18: 1 | J18: 0 | K18: 0 | L18: 8 | M18: =C18+H18 -> 0 | N18: =D18+I18 -> 1 | O18: =E18+J18 -> 1 | P18: =F18+K18 -> 1 | Q18: =G18+L18 -> 14 | R18: =M18+N18+2*O18-P18*0.5 -> 2.5
A19: 66 | B19: Jackie Wang | C19: 0 | D19: 0 | E19: 0 | F19: 1 | G19: 10 | H19: 1 | I19: 2 | J19: 0 | K19: 1 | L19: 13 | M19: =C19+H19 -> 1 | N19: =D19+I19 -> 2 | O19: =E19+J19 -> 0 | P19: =F19+K19 -> 2 | Q19: =G19+L19 -> 23 | R19: =M19+N19+2*O19-P19*0.5 -> 2
A20: 21 | B20: Jess Oh | C20: 0 | D20: 1 | E20: 0 | F20: 1 | G20: 11 | H20: 0 | I20: 1 | J20: 0 | K20: 0 | L20: 12 | M20: =C20+H20 -> 0 | N20: =D20+I20 -> 2 | O20: =E20+J20 -> 0 | P20: =F20+K20 -> 1 | Q20: =G20+L20 -> 23 | R20: =M20+N20+2*O20-P20*0.5 -> 1.5
A21: 33 | B21: Amanda Murphy | C21: 1 | D21: 0 | E21: 0 | F21: 0 | G21: 19 | H21: 0 | I21: 1 | J21: 0 | K21: 2 | L21: 15 | M21: =C21+H21 -> 1 | N21: =D21+I21 -> 1 | O21: =E21+J21 -> 0 | P21: =F21+K21 -> 2 | Q21: =G21+L21 -> 34 | R21: =M21+N21+2*O21-P21*0.5 -> 1
A22: 99 | B22: Emily Kiver | C22: 0 | D22: 1 | E22: 0 | F22: 0 | G22: 7 | H22: 0 | I22: 0 | J22: 0 | K22: 0 | L22: 12 | M22: =C22+H22 -> 0 | N22: =D22+I22 -> 1 | O22: =E22+J22 -> 0 | P22: =F22+K22 -> 0 | Q22: =G22+L22 -> 19 | R22: =M22+N22+2*O22-P22*0.5 -> 1
A23: 10 | B23: Sydney Rehder | C23: 0 | D23: 0 | E23: 0 | F23: 0 | G23: 6 | H23: 0 | I23: 0 | J23: 0 | K23: 1 | L23: 7 | M23: =C23+H23 -> 0 | N23: =D23+I23 -> 0 | O23: =E23+J23 -> 0 | P23: =F23+K23 -> 1 | Q23: =G23+L23 -> 13 | R23: =M23+N23+2*O23-P23*0.5 -> -0.5
A24: 17 | B24: Maggie Pendleton | C24: 0 | D24: 0 | E24: 0 | F24: 2 | G24: 13 | H24: 0 | I24: 0 | J24: 0 | K24: 0 | L24: 14 | M24: =C24+H24 -> 0 | N24: =D24+I24 -> 0 | O24: =E24+J24 -> 0 | P24: =F24+K24 -> 2 | Q24: =G24+L24 -> 27 | R24: =M24+N24+2*O24-P24*0.5 -> -1

Sheet RAL
A1: Jersey # | B1: Full Name | C1: Goals | D1: Assists | E1: Blocks | F1: Turnovers | G1: Points played
A2: 2 | B2: Claire Bidigare-Curtis | C2: 1 | D2: 0 | E2: 1 | F2: 0 | G2: 21
A3: 3 | B3: Lyra Olson | C3: 0 | D3: 1 | E3: 1 | F3: 1 | G3: 13
A4: 6 | B4: Jenny Wei | C4: 2 | D4: 1 | E4: 0 | F4: 0 | G4: 20
A5: 9 | B5: Jinny Riedel | C5: 0 | D5: 1 | E5: 0 | F5: 1 | G5: 10
A6: 12 | B6: Katie Backus Meilstrup | C6: 0 | D6: 0 | E6: 0 | F6: 0 | G6: 0
A7: 14 | B7: Ellen Yu | C7: 0 | D7: 0 | E7: 0 | F7: 1 | G7: 14
A8: 15 | B8: Carmen Tormey | C8: 0 | D8: 0 | E8: 0 | F8: 0 | G8: 9
A9: 17 | B9: Karen Ehrhardt | C9: 2 | D9: 0 | E9: 1 | F9: 1 | G9: 15
A10: 18 | B10: Sarah McKee | C10: 0 | D10: 0 | E10: 0 | F10: 0 | G10: 10
A11: 19 | B11: Sydney Kelley | C11: 0 | D11: 0 | E11: 0 | F11: 0 | G11: 0
A12: 21 | B12: Julia Hoffmann | C12: 3 | D12: 1 | E12: 0 | F12: 0 | G12: 12
A13: 22 | B13: Julia Zwierzynski | C13: 0 | D13: 1 | E13: 1 | F13: 1 | G13: 20
A14: 24 | B14: Hannah Boettcher | C14: 1 | D14: 0 | E14: 0 | F14: 0 | G14: 21
... A24: 88 | B24: Maddie Pletzke | C24: 0 | D24: 0 | E24: 2 | F24: 1 | G24: 11

Sheet Points
A1: Point | B1: Pulling team | C1: Scoring team | D1: Clean?
A2: 1 | B2: RAL | C2: DC | D2: TRUE
A3: 2 | B3: DC | C3: RAL | D3: TRUE
A4: 3 | B4: RAL | C4: DC | D4: TRUE
A5: 4 | B5: DC | C5: DC | D5: FALSE
A6: 5 | B6: DC | C6: RAL | D6: TRUE
A7: 6 | B7: RAL | C7: DC | D7: TRUE
A8: 7 | B8: DC | C8: RAL | D8: FALSE
A9: 8 | B9: RAL | C9: DC | D9: FALSE
A10: 9 | B10: DC | C10: RAL | D10: FALSE
A11: 10 | B11: RAL
A12: 11 | B12: DC | C12: RAL | D12: TRUE
A13: 12 | B13: RAL | C13: DC | D13: FALSE
A14: 13 | B14: DC | C14: DC | D14: TRUE
A15: 14 | B15: DC | C15: DC | D15: TRUE
A16: 15 | B16: DC | C16: DC | D16: FALSE
A17: 16 | B17: DC | C17: RAL | D17: TRUE
A18: 17 | B18: RAL | C18: RAL | D18: TRUE
A19: 18 | B19: RAL | C19: DC | D19: TRUE
A20: 19 | B20: DC | C20: DC | D20: TRUE
A21: 20 | B21: RAL | C21: DC | D21: FALSE
A22: 21 | B22: DC | C22: RAL | D22: FALSE
A23: 22 | B23: RAL | C23: DC | D23: TRUE
A24: 23 | B24: DC | C24: RAL | D24: TRUE
A25: 24 | B25: RAL | C25: DC | D25: TRUE
A26: 25 | B26: DC | C26: RAL | D26: TRUE
A27: 26 | B27: RAL | C27: DC | D27: TRUE
A28: 27 | B28: DC | C28: RAL | D28: TRUE
A29: 28 | B29: RAL | C29: RAL | D29: TRUE
A30: 29 | B30: RAL | C30: DC | D30: TRUE
A31: 30 | B31: DC | C31: RAL | D31: TRUE
A32: 31 | B32: RAL
A33: 32 | B33: DC | C33: RAL | D33: TRUE
A34: 33 | B34: RAL | C34: RAL | D34: TRUE
A35: 34 | B35: RAL | C35: RAL | D35: TRUE
A36: 35 | B36: RAL | C36: DC | D36: TRUE
A37: 36 | B37: DC | C37: DC | D37: TRUE
A38: 37 | B38: DC | C38: RAL | D38: TRUE
A39: 38 | B39: RAL
A40: 39
...

Sheet Game summary
A1: Team | B1: DC | C1: RAL
A2: Points | B2: =countif(Points!$C1:$C51, B$1) -> 18 | C2: =countif(Points!$C1:$C51, C$1) -> 17
A3: Holds | B3: =countifs(Points!C1:C51, B$1, Points!B1:B51, C$1) -> 12 | C3: =countifs(Points!C1:C51, C$1, Points!B1:B51, B$1) -> 13
A4: Breaks | B4: =countifs(Points!$C1:$C51, B$1, Points!$B1:$B51, B$1) -> 6 | C4: =countifs(Points!$C1:$C51, C$1, Points!$B1:$B51, C$1) -> 4
A5: Clean holds | B5: =countifs(Points!C1:C51, B$1, Points!B1:B51, C$1, Points!D1:D51,"TRUE") -> 9 | C5: =countifs(Points!C1:C51, C$1, Points!B1:B51, B$1, Points!D1:D51,"TRUE") -> 10
